Workbook

Sheet 0_README
A1: DAY 22 — SMARTCHECK-IN KIOSK
A2: Đinh Xuân Quyền · 2A202602358 · Trước kiểm thử · 08/10/2026
A4: QUY ƯỚC MÀU — CHỈ ĐIỀN VÀO Ô MÀU VÀNG | G4: PHẠM VI VÀ CÁCH ĐỌC
A5: Ô VÀNG, chữ xanh dương | B5: Ô bạn phải điền | G5: Trạng thái | H5: Đang triển khai, chưa kiểm thử | I5: Số vận hành, giá bán, CAC là giả định có giải thích.
A6: Ô XÁM, chữ đen | B6: Công thức tự tính — KHÔNG SỬA | G6: Đơn vị kinh tế | H6: 1 khách sạn / 1 tháng | I6: Kịch bản mục tiêu 10 khách sạn, chưa đạt hiện tại.
A7: Chữ xanh lá | B7: Link sang tab khác | G7: Phân khúc đề xuất | H7: Khách sạn 120 phòng tại Việt Nam | I7: Booking đơn có 1 người cần eKYC; nhóm khách chưa thuộc phạm vi pilot.
A8: Ô XÁM đậm nhạt | B8: Bảng tham chiếu, chỉ đọc | G8: Thiết bị | H8: Khách sạn tự trang bị | I8: Không bán kiosk, camera hoặc máy cấp thẻ.
G9: Phạm vi job | H9: eKYC + CHECKED_IN + room_assigned | I9: Không đồng nghĩa cấp chìa khóa hay chứng minh giấy tờ là thật.
A10: THỨ TỰ LÀM — 6 TRẠM, 120 PHÚT | G10: Mô hình giá | H10: Hybrid: $30/tháng + $0.11/hồ sơ | I10: Cap 1,200 hồ sơ; phí nền không bao gồm lượt miễn phí.
A11: Trạm 1 · 15' | B11: Ngân sách khách & định nghĩa Job → điền S1–S2 của tab 1_Cost_Job | G11: Case tính tiền | H11: hotel_id + booking_id + arrival_id | I11: Một lần khi booking hợp lệ và bắt đầu OCR; retry không thu thêm.
A12: Trạm 2 · 20' | B12: Value Metric → tab 3_Value_Metric | G12: HITL | H12: A: lễ tân khách sạn xử lý ca lỗi | I12: QA nội bộ và support của nhà cung cấp có trong COGS.
A13: Trạm 3 · 30' | B13: Cost/Job, giá sàn & giá trần → tab 1_Cost_Job (S3–S8) rồi 2_Pricing | G13: Khớp mẫu | H13: Giữ nguyên công thức xám gốc | I13: B41 vàng gom API eKYC + retry + infra từ khối chi tiết; không giả thành token.
A14: Trạm 4 · 20' | B14: Kênh phân phối & Affordability Test → tab 4_Channel_Fit | G14: Giá/job tab 2 | H14: Đơn giá quy đổi từ Hybrid | I14: Hóa đơn không tính theo số check-in thành công.
A15: Trạm 5 · 15' | B15: Pain Moment & 90-Day Plan → tab 5_90Day_Plan | G15: Containment tài chính | H15: Không có ngưỡng riêng ở N cố định | I15: Hybrid + HITL A: doanh thu và COGS không đổi theo containment.
A16: Trạm 6 · 20' | B16: Evidence Pack & ráp One-Pager → tab 5_90Day_Plan + file .docx | G16: Ngưỡng dùng để quyết định | H16: 81% để giá <=25% giá trị tiết kiệm | I16: GM>=60%: >=181 hồ sơ; giá>=3xCOGS: >=735 hồ sơ/tháng, cohort 10. Xem tab2 H56:H60.
G17: Sensitivity gốc | H17: Chỉ tham chiếu Outcome giá cố định | I17: Không dùng B33/B35 và A39:D44 kết luận cho Hybrid.
A18: 3 QUY TẮC KHÔNG ĐƯỢC PHÁ | G18: Trước pilot | H18: PMS dự kiến: Mews Connector API | I18: Chưa có quyền API/hotel dùng Mews xác nhận; xem PMS_Integration.md.
A19: 1. Chia cho số job HOÀN THÀNH, không phải số job đã thử. | G19: Loại khỏi gói | H19: Thiết bị, thanh toán, thuế, cấp thẻ | I19: Nếu bán thêm phải tính lại chi phí và hợp đồng.
A20: 2. HITL và Retry không được để 0 nếu không có lý do viết ra được. | G20: Người phụ trách | H20: Đinh Xuân Quyền | I20: Tên theo thư mục bài; chưa có khách/pilot/partner xác nhận.
A21: 3. Mọi con số giá API phải có NGÀY kiểm tra (xem tab 6_Benchmarks). | G21: Bài test người lạ | H21: Đã thực hiện - Đạt | I21: 12:10 ngày 08/10/2026; Đỗ Trường Thành Ân: đủ 3 ý, hỏi lại 2 câu. Theo biên bản người học cung cấp.
A23: Giá mẫu cũ không dùng trong bài. Nguồn áp dụng đã kiểm tra 08/10/2026 ở 6_Benchmarks!G:J.
A24: Đọc khối G:J tab 2: Hybrid khác Outcome. Chưa có eval, khách hàng hay pilot thực tế.

Sheet 1_Cost_Job
A1: TAB 1 — COST/JOB CALCULATOR
A2: Trạm 1 (S1–S2) và Trạm 3 (S3–S8). Chỉ điền ô vàng.
A4: S1. ĐỊNH NGHĨA JOB | G4: GIẢ ĐỊNH VÀ CHI PHÍ eKYC
A5: 1 job của bạn là gì? | B5: 1 lượt eKYC đạt và check-in tự động: CHECKED_IN + room_assigned; không HITL. | D5: Một arrival chỉ hoàn thành 1 lần; session mới/F5 không sinh check-in mới. | G5: Khách sạn chia platform | H5: 10 | I5: Mục tiêu tương lai, chưa có khách trả tiền.
A6: Biến thể HITL: A hay B? | B6: A | D6: A = khách tự xử lý ca escalate · B = BẠN chịu (outcome/managed) | G6: Hosting + DB toàn cohort / tháng ($) | H6: 60 | I6: Giả định cố định, dùng chung một platform.
G7: Support / hotel / tháng ($) | H7: 6 | I7: 1.5 giờ x $4, không gồm onboarding.
A8: S2. KHỐI LƯỢNG | G8: Connector PMS / hotel / tháng ($) | H8: 2.4 | I8: $28.8/năm phân bổ, dùng cùng một PMS.
A9: Số job THỬ / tháng | B9: 1200 | C9: job | G9: OCR / ảnh ($) | H9: 0.0015 | I9: Google Vision Document Text Detection, không hưởng free tier.
A10: Containment rate (AI tự làm xong) | B10: 0.85 | D10: 85% là giả định, chưa là eval. Auto-PASS có retry vẫn tính containment; STP khác. | G10: Ảnh giấy tờ / hồ sơ | H10: 2 | I10: Hai mặt CCCD; passport tạm dự phòng 2 ảnh.
A11: → Số job HOÀN THÀNH / tháng | B11: =B9*B10 -> 1020 | C11: job | D11: MẪU SỐ của Cost/Job | G11: Face API / ảnh phân tích ($) | H11: 0.001 | I11: AWS Group1/2 bậc đầu, tham chiếu US.
A12: → Số job KHÔNG xong / tháng | B12: =B9-B11 -> 180 | C12: job | D12: Số ca phải escalate | G12: Số ảnh Face API tính phí / hồ sơ | H12: 3 | I12: 2 DetectFaces + 1 CompareFaces; không đếm thêm vì API có 2 ảnh đầu vào.
G13: Liveness / check ($) | H13: 0.015 | I13: AWS US East (N. Virginia), giá tham chiếu công khai.
A14: S3. API — LLM | G14: Liveness check / hồ sơ | H14: 1 | I14: Retry tính riêng.
A15: Giá input ($ / 1M token) | B15: 0 | D15: Không dùng LLM. Giá token =0 có lý do; eKYC tính theo ảnh/check ở G:H. | G15: OCR / job thử ($) | H15: =H9*H10 -> 0.003 | I15: OCR không chứng minh giấy tờ thật.
A16: Giá output ($ / 1M token) | B16: 0 | G16: Face matching + detection / job thử ($) | H16: =H11*H12 -> 0.003 | I16: Đối chiếu 1:1; không tạo face collection.
A17: Giá cache WRITE ($ / 1M token) | B17: 0 | D17: Không áp dụng prompt cache; không tái sử dụng kết quả xác minh cũ. | G17: Liveness / job thử ($) | H17: =H13*H14 -> 0.015 | I17: Không đồng nghĩa tính hợp lệ của giấy tờ.
A18: Giá cache READ ($ / 1M token) | B18: 0 | D18: Không có LLM cache. | G18: API eKYC tổng / job thử ($) | H18: =SUM(H15:H17) -> 0.021 | I18: OCR + Face API + liveness.
A19: Số lượt (turns) / job | B19: 1 | C19: lượt | D19: Giữ 1 lượt kỹ thuật để công thức (turns-1) không âm; token đều 0. | G19: Retry eKYC / job thử ($) | H19: =H18*B46 -> 0.00168 | I19: 8% x 1 vòng đầy đủ; không thu thêm khách.
A20: Token input CACHE ĐƯỢC / lượt | B20: 0 | C20: token | D20: System prompt + KB + few-shot
A21: Token input FRESH / lượt | B21: 0 | C21: token | D21: Câu hỏi khách + dữ liệu động | G21: Hosting / job thử ($) | H21: =H6/H5/B9 -> 0.005 | I21: Chi phí cố định chia theo cohort và N.
A22: Token output / lượt | B22: 0 | C22: token | G22: Storage + network / job thử ($) | H22: 0.002 | I22: Ước lượng; không giữ video dài hạn.
A23: → Cache write / job | B23: =B20*B17/1000000 -> 0 | G23: Logging + eval / job thử ($) | H23: 0.002 | I23: Ước lượng, có regression eval phân bổ.
A24: → Cache read / job | B24: =(B19-1)*B20*B18/1000000 -> 0 | G24: Support / job thử ($) | H24: =H7/B9 -> 0.005 | I24: Chi phí tháng / N.
A25: → Input fresh / job | B25: =B19*B21*B15/1000000 -> 0 | G25: Connector / job thử ($) | H25: =H8/B9 -> 0.002 | I25: Không gồm setup ban đầu.
A26: → Output / job | B26: =B19*B22*B16/1000000 -> 0 | G26: Infra tổng / job thử ($) | H26: =SUM(H21:H25) -> 0.016 | I26: Không gồm API eKYC và retry.
A27: → LLM / job — CÓ prompt caching | B27: =SUM(B23:B26) -> 0
A28: → LLM / job — KHÔNG cache | B28: =B19*(B20+B21)*B15/1000000+B26 -> 0 | G28: API eKYC / tháng ($) | H28: =H18*B9 -> 25.2
A29: → % tiết kiệm nhờ caching | B29: =IF(B28=0,0,1-B27/B28) -> 0 | D29: Đòn bẩy rẻ nhất bạn có | G29: Retry eKYC / tháng ($) | H29: =H19*B9 -> 2.016
A30: Dùng Batch API? (1 = có, 0 = không) | B30: 0 | D30: Không Batch vì khách cần nhận phòng ngay. | G30: Infra / tháng ($) | H30: =H26*B9 -> 19.2
A31: → LLM / job sau Batch | B31: =B27*(1-B30*0.5) -> 0 | G31: QA / tháng ($) | H31: =B54 -> 4.8
G32: COGS / tháng ($) | H32: =SUM(H28:H31)+B55 -> 51.216 | I32: API + retry + infra + QA + escalation nếu B; đối chiếu B62+B63.
A33: S4. API — SPEECH (để 0 nếu sản phẩm không có thoại) | G33: Overhead / tháng ($) | H33: =B59 -> 30 | I33: Tách khỏi COGS.
A34: Giá STT ($ / phút) | B34: 0 | D34: Không thoại: STT/TTS/telephony =0. | G34: Tổng có overhead / tháng ($) | H34: =H32+H33 -> 81.216
A35: Số phút audio / job | B35: 0 | C35: phút
A36: Giá TTS ($ / 1M ký tự) | B36: 0 | D36: ElevenLabs Flash $50 · Google Standard $4 | G36: Phòng / khách sạn | H36: 120 | I36: Ngách đề xuất, cần cùng PMS.
A37: Số ký tự TTS / job | B37: 0 | C37: ký tự | D37: ≈ 900 ký tự cho mỗi phút bot nói | G37: Occupancy | H37: 0.8 | I37: Giả định, không phải thống kê ngành.
A38: → Speech / job | B38: =B34*B35+B36*B37/1000000 -> 0 | G38: Ngày / tháng | H38: 30 | I38: Tháng chuẩn.
G39: Số đêm / booking | H39: 2 | I39: Giả định.
A40: S5. INFRA | G40: Lượt đến tiềm năng / tháng | H40: =H36*H37*H38/H39 -> 1440
A41: eKYC + infra + retry eKYC / job thử ($) | B41: =H18+H19+H26 -> 0.03868 | D41: Khối G:H tách API, retry và infra; dùng B41 vàng để giữ công thức xám. | G41: Tỷ lệ vào kiosk | H41: =B9/H40 -> 0.83333333 | I41: 83.33% giả định đạt N=1200.
...

Sheet 2_Pricing
A1: TAB 2 — PRICING SANITY CHECK
A2: Trạm 3. Cost/Job tự lấy từ tab 1. Bạn điền giá bán và các con số neo giá.
A4: GIÁ SÀN | G4: PRICING HYBRID ÁP DỤNG
A5: Cost/Job (từ tab 1_Cost_Job) | B5: ='1_Cost_Job'!B66 -> 0.050211765 | C5: $/job | G5: Phí nền / hotel / tháng ($) | H5: ='1_Cost_Job'!H45 -> 30 | I5: Không gồm lượt miễn phí.
A6: Hệ số an toàn tối thiểu | B6: 3 | C6: × | D6: Giá bán ≥ 3 × Cost/Job | G6: Phí / hồ sơ đủ điều kiện ($) | H6: ='1_Cost_Job'!H46 -> 0.11 | I6: Usage tính từ hồ sơ đầu.
A7: → GIÁ SÀN | B7: =B5*B6 -> 0.15063529 | C7: $/job | G7: Hồ sơ đủ điều kiện / tháng | H7: ='1_Cost_Job'!B9 -> 1200 | I7: Cap 1200, không đếm retry vào N.
G8: Doanh thu định kỳ / tháng ($) | H8: =H5+H6*H7 -> 162 | I8: Không gồm setup/thiết bị/thuế.
A9: GIÁ TRẦN — NEO THEO THỨ KHÁCH ĐANG CHI | G9: Job hoàn thành / tháng | H9: ='1_Cost_Job'!B11 -> 1020 | I9: 85% là giả định.
A10: Giá trị khách tiết kiệm được / tháng ($) | B10: ='1_Cost_Job'!H44 -> 680 | D10: Neo theo giá trị | G10: COGS / tháng ($) | H10: ='1_Cost_Job'!H32 -> 51.216
A11: Số job / tháng của 1 khách | B11: ='1_Cost_Job'!B11 -> 1020 | C11: job | G11: Lãi gộp / tháng ($) | H11: =H8-H10 -> 110.784
A12: → Trần theo giá trị — mức 10% | B12: =IF(B11=0,0,B10*0.1/B11) -> 0.066666667 | C12: $/job | G12: GM Hybrid | H12: =H11/H8 -> 0.68385185 | I12: Đồng nhất B21 tại kịch bản hiện tại.
A13: → Trần theo giá trị — mức 25% | B13: =IF(B11=0,0,B10*0.25/B11) -> 0.16666667 | C13: $/job | G13: Lãi sau overhead phân bổ ($) | H13: =H11-'1_Cost_Job'!B59 -> 80.784 | I13: Không là lợi nhuận ròng công ty.
A14: Lương / tháng của vị trí bị thay ($) | B14: 704 | D14: Neo theo nhân công | G14: Giá bán / giá trị thời gian | H14: =H8/'1_Cost_Job'!H44 -> 0.23823529 | I14: Không cam kết giảm biên chế.
A15: → Trần theo nhân công — mức 50% | B15: =IF(B11=0,0,B14*0.5/B11) -> 0.34509804 | C15: $/job
A16: → Trần theo nhân công — mức 70% | B16: =IF(B11=0,0,B14*0.7/B11) -> 0.48313725 | C16: $/job | G16: Chi phí cố định / hotel / tháng ($) | H16: ='1_Cost_Job'!H6/'1_Cost_Job'!H5+'1_Cost_Job'!H7+'1_Cost_Job'!H8 -> 14.4 | I16: Hosting + support + connector.
G17: Chi phí biến đổi / hồ sơ ($) | H17: ='1_Cost_Job'!H18+'1_Cost_Job'!H19+'1_Cost_Job'!H22+'1_Cost_Job'!H23+B30+B31*(1-B34) -> 0.03068 | I17: API + retry + storage/network + log/eval + QA.
A18: GIÁ BÁN CỦA BẠN | G18: Kiểm tra COGS khớp (=0) | H18: =H10-(H16+H17*H7) -> 0
A19: Giá quy đổi / job hoàn thành (Hybrid) | B19: =H8/H9 -> 0.15882353 | C19: $/job | D19: Hóa đơn = $30 + $0.11 x hồ sơ xử lý đủ điều kiện; xem H8.
A20: → Bội số so với Cost/Job | B20: =IF(B5=0,0,B19/B5) -> 3.163074 | G20: Hồ sơ tối thiểu cho GM>=60% | H20: =MAX(0,(H16-(1-B32)*H5)/((1-B32)*H6-H17)) -> 180.18018 | I20: Chỉ dùng nếu H21>0, làm tròn lên ở H22.
A21: → GROSS MARGIN | B21: =IF(B19=0,0,(B19-B5)/B19) -> 0.68385185 | G21: Đóng góp đạt GM mục tiêu / hồ sơ | H21: =H6*(1-B32)-H17 -> 0.01332 | I21: Phải >0, nếu không giá cần tính lại.
A22: → Đèn: bội số ≥ 3? | B22: =IF(B20>=B6,"OK — ĐẠT","KHÔNG ĐẠT — quay lại tab 1") -> OK — ĐẠT | G22: Ngưỡng hồ sơ nguyên / tháng | H22: =IF(H21<=0,"Không khả thi",ROUNDUP(H20,0)) -> 181 | I22: Chỉ ngưỡng GM60%; ngưỡng đồng thời giá>=3xCost/Job ở H60.
A23: → Đèn: Gross Margin | B23: =IF(B21>=0.6,"OK — AN TOÀN (≥60%)",IF(B21>=0.5,"CẢNH BÁO (50–60%)","NGUY HIỂM (<50%)")) -> OK — AN TOÀN (≥60%) | G23: Containment tài chính, N cố định | H23: Không có ngưỡng riêng | I23: Với Hybrid + HITL A, doanh thu và COGS không đổi theo c.
A24: → Đèn: GM có cao bất thường? | B24: =IF(B21>0.85,"NGHI NGỜ — nhiều khả năng bạn quên một khoản chi phí","OK") -> OK | G24: Containment để giá <=25% giá trị | H24: =H8/(H7*'1_Cost_Job'!H42/60*'1_Cost_Job'!H43*'1_Cost_Job'!H48) -> 0.81 | I24: 81%, là ngưỡng ROI khách, không phải GM.
A25: → Giá bán nằm trong vùng neo? | B25: =IF(AND(B19>=B7,B19<=MAX(B13,B16)),"OK — trong vùng giá bán","XEM LẠI — ngoài vùng giá sàn/trần") -> OK — trong vùng giá bán | G25: Containment mục tiêu | H25: ='1_Cost_Job'!B10 -> 0.85 | I25: Chưa có eval chứng minh.
A27: THAM CHIẾU OUTCOME — KHÔNG PHẢI NGƯỠNG HYBRID | G27: Cohort 2 hotel: COGS/hotel ($) | H27: ='1_Cost_Job'!H6/2+'1_Cost_Job'!H7+'1_Cost_Job'!H8+H17*H7 -> 75.216 | I27: Giữ N=1200 để tách ảnh hưởng cohort; pilot volume thấp sẽ còn kém.
A28: Ký hiệu: v = chi phí biến đổi / job thử · q = QA / job thử · e = chi phí 1 ca escalate | G28: Cohort 2 hotel: GM | H28: =1-H27/H8 -> 0.5357037 | I28: Chưa đạt 60%; pilot là ngân sách học.
A29: v — chi phí biến đổi / job thử | B29: ='1_Cost_Job'!B31+'1_Cost_Job'!B38+'1_Cost_Job'!B43+'1_Cost_Job'!B47 -> 0.03868 | G29: Cohort tối thiểu cho GM>=60% | H29: =ROUNDUP('1_Cost_Job'!H6/((1-B32)*H8-'1_Cost_Job'!H7-'1_Cost_Job'!H8-H17*H7),0) -> 4 | I29: 4 hotel nếu mỗi hotel đạt N=1200.
A30: q — QA nội bộ / job thử | B30: ='1_Cost_Job'!B51*('1_Cost_Job'!B52/60)*'1_Cost_Job'!B50 -> 0.004
A31: e — chi phí 1 ca escalate | B31: =IF('1_Cost_Job'!B6="B",('1_Cost_Job'!B53/60)*'1_Cost_Job'!B50,0) -> 0 | G31: Trần doanh thu từ 25% giá trị ($) | H31: ='1_Cost_Job'!H44*'1_Cost_Job'!H48 -> 170 | I31: Chưa là giá khách sẵn lòng trả.
A32: Gross Margin mục tiêu | B32: 0.6 | G32: Sàn doanh thu (=3 x COGS) ($) | H32: =3*H10 -> 153.648
A33: Containment tham chiếu nếu giá/job cố định | B33: =IF((B19*(1-B32)+B31)=0,0,(B29+B30+B31)/(B19*(1-B32)+B31)) -> 0.67181481 | D33: Chỉ xét khi chuyển sang Outcome; không dùng kết luận B35 cho Hybrid. | G33: Vùng giá cơ sở | H33: =IF(H32<=H31,"Có vùng giá","Chưa có vùng giá") -> Có vùng giá | I33: $153.648-$170, chọn $162.
A34: Containment hiện tại (từ tab 1) | B34: ='1_Cost_Job'!B10 -> 0.85
A35: Kết luận riêng kịch bản Outcome tham chiếu | B35: =IF(B34>=B33,"ĐẠT — mô hình có lãi lành mạnh","CHƯA ĐẠT — phải tăng containment, tăng giá, hoặc đổi biến thể HITL") -> ĐẠT — mô hình có lãi lành mạnh | G35: Hệ số tăng toàn bộ giá API | H35: 1 | I35: Đổi thành 2 để stress.
G36: COGS sau stress API ($) | H36: =H10+('1_Cost_Job'!H28+'1_Cost_Job'!H29)*(H35-1) -> 51.216 | I36: Không stress infra trong phép thử này.
A37: SENSITIVITY OUTCOME THAM CHIẾU — HYBRID XEM G:H | G37: GM sau stress API | H37: =1-H36/H8 -> 0.68385185
A38: Containment | B38: Cost/Job | C38: Gross Margin | D38: Đánh giá
A39: 0.5 | B39: =($B$29+$B$30+$B$31*(1-A39))/A39 -> 0.08536 | C39: =IF($B$19=0,0,1-B39/$B$19) -> 0.46254815 | D39: =IF(C39>=0.6,"An toàn",IF(C39>=0.5,"Cảnh báo","Nguy hiểm")) -> Nguy hiểm | G39: Ngân sách học pilot 90 ngày ($) | H39: 500 | I39: Trần kế hoạch, chưa chi.
A40: 0.6 | B40: =($B$29+$B$30+$B$31*(1-A40))/A40 -> 0.071133333 | C40: =IF($B$19=0,0,1-B40/$B$19) -> 0.55212346 | D40: =IF(C40>=0.6,"An toàn",IF(C40>=0.5,"Cảnh báo","Nguy hiểm")) -> Cảnh báo | G40: Tham chiếu Outcome: c tại GM50% | H40: =IF(B19=0,"n.a.",(B29+B30)/(B19*0.5)) -> 0.53745185 | I40: Không là ngưỡng mất tiền Hybrid.
A41: 0.7 | B41: =($B$29+$B$30+$B$31*(1-A41))/A41 -> 0.060971429 | C41: =IF($B$19=0,0,1-B41/$B$19) -> 0.61610582 | D41: =IF(C41>=0.6,"An toàn",IF(C41>=0.5,"Cảnh báo","Nguy hiểm")) -> An toàn
A42: 0.8 | B42: =($B$29+$B$30+$B$31*(1-A42))/A42 -> 0.05335 | C42: =IF($B$19=0,0,1-B42/$B$19) -> 0.66409259 | D42: =IF(C42>=0.6,"An toàn",IF(C42>=0.5,"Cảnh báo","Nguy hiểm")) -> An toàn
...

Sheet 3_Value_Metric
A1: TAB 3 — VALUE METRIC SCORECARD
A2: Trạm 2. Chấm 0 / 1 / 2 điểm cho mỗi câu, theo THỰC TẾ HÔM NAY.
A4: A. ATTRIBUTION — bạn đo được kết quả là do AI tạo ra không? | G4: CƠ SỞ CHẤM VÀ QUY TẮC TÍNH TIỀN
A5: 1. Tôi có log đầy đủ mỗi job AI xử lý, gắn được với kết quả cuối cùng | B5: 0 | G5: Attribution | H5: 0,0,0,1,2 | I5: Chưa có log/eval/buyer approval; có thiết kế attribution và định nghĩa job.
A6: 2. Tôi có bộ eval đo được tỷ lệ AI làm đúng, có số liệu | B6: 0 | G6: Autonomy | H6: 1,0,1,0,0 | I6: Luồng tự động/handoff mới là thiết kế, chưa chứng minh vận hành.
A7: 3. Khách hàng đồng ý với cách tôi định nghĩa 'thành công' của một job | B7: 0 | G7: Tính tiền khi | H7: Booking hợp lệ, bắt đầu OCR | I7: Một case theo hotel_id + booking_id + arrival_id.
A8: 4. Tôi phân biệt được kết quả do AI tạo ra với kết quả do yếu tố khác | B8: 1 | G8: Không tính tiền | H8: Sai booking, bỏ trước API, duplicate | I8: Retry cùng case không thu thêm.
A9: 5. Tôi viết được định nghĩa chặt như Intercom: cái gì tính tiền, cái gì không | B9: 2 | G9: Ca eKYC thất bại | H9: Có usage nếu API đã xử lý | I9: Chuyển lễ tân; không cam kết outcome, khách biết trước quy tắc.
A10: → ĐIỂM ATTRIBUTION (tối đa 10) | B10: =SUM(B5:B9) -> 3 | G10: Tranh chấp | H10: Xuất case ledger, refund ghi trùng | I10: Cần started_at và idempotency key; chưa có hợp đồng thực.
G11: Phí nền mua gì | H11: Dashboard, 1 PMS, giám sát, support | I11: 1.5 giờ support/hotel/tháng, chưa SLA 24/7.
A12: B. AUTONOMY — AI tự chạy hay cần người? | G12: Điều kiện thử Outcome | H12: Có eval và buyer approval | I12: Chỉ sau pilot có số đo và định nghĩa outcome được thống nhất.
A13: 1. AI hoàn thành job từ đầu đến cuối, không cần người bấm nút giữa chừng | B13: 1 | G13: Giới hạn Chekin | H13: Giá từ cấu hình property mặc định | I13: Mức từ €3.95/property/tháng theo thanh toán năm; không là giá hotel/kiosk.
A14: 2. Job chạy được ngoài giờ hành chính mà không ai trực | B14: 0 | G14: Giới hạn Duve | H14: Gói Basic chưa là eKYC kiosk trọn gói | I14: Automation và một số tính năng có phụ phí.
A15: 3. Khi AI không chắc, nó tự chuyển tiếp đúng chỗ — không cần người phân loại | B15: 1 | G15: Ngày kiểm tra nguồn | H15: 08/10/2026 | I15: Benchmark đơn vị tính tiền, không lấy làm giá trần.
A16: 4. Tỷ lệ ca phải có người can thiệp dưới 20% | B16: 0
A17: 5. Người vận hành chỉ kiểm tra mẫu (QA), không xử lý từng ca | B17: 0
A18: → ĐIỂM AUTONOMY (tối đa 10) | B18: =SUM(B13:B17) -> 2
A20: GỢI Ý CỦA MODEL
A21: → Value Metric gợi ý | B21: =IF(AND(B10>=7,B18>=7),"OUTCOME",IF(AND(B10>=7,B18<7),"USAGE",IF(AND(B10<7,B18>=7),"USAGE (an toàn)","SEAT hoặc HYBRID"))) -> SEAT hoặc HYBRID
A22: Ngưỡng 7/10 là quy ước của bài tập, không phải chuẩn ngành — dùng để buộc bạn ra quyết định, không phải để thay bạn quyết định.
A24: BENCHMARK NGƯỢC — 2 sản phẩm thật cùng loại job
A25: Tên sản phẩm | B25: Value Metric | C25: Giá công bố | D25: Link nguồn
A26: Chekin | B26: Subscription/property | C26: Từ €3.95/property/tháng, thanh toán năm; hotel cần cấu hình/báo giá | D26: https://chekin.com/en/pricing/
A27: Duve | B27: Subscription theo gói | C27: Basic tối thiểu $120/tháng; automation có phụ phí | D27: https://duve.com/pricing/
A29: QUYẾT ĐỊNH CUỐI
A30: Value Metric tôi chọn | B30: Hybrid
A31: Nếu KHÁC gợi ý — lý do thị trường là gì? | B31: Khớp gợi ý; chưa có eval hay khách chấp thuận outcome.
A32: Decision Note — câu 1: tôi chọn đơn vị nào? | B32: Chọn phí nền $30/khách sạn/tháng + $0.11/hồ sơ eKYC đủ điều kiện, cap 1200 hồ sơ/tháng.
A33: Decision Note — câu 2: bằng chứng Attribution / Autonomy? | B33: Attribution 3/10, Autonomy 2/10: mới có thiết kế event và luồng tự động; chưa có audit log hoặc kết quả eval.
A34: Decision Note — câu 3: mô hình này lỗ trong tình huống nào? | B34: Không đạt GM khi ít khách chia hosting, volume thấp, API/support tăng. Retry không được tính thêm cho khách.

Sheet 4_Channel_Fit
A1: TAB 4 — CHANNEL FIT & AFFORDABILITY TEST
A2: Trạm 4. Chọn ĐÚNG 1 kênh cho 90 ngày đầu — và chứng minh bằng số.
A4: A. NGÂN SÁCH CAC — bạn nuôi nổi kênh nào? | G4: KIỂM CHỨNG SALES-LED
A5: ARPU / tháng ($) | B5: ='2_Pricing'!H8 -> 162 | G5: Motion | H5: Founder-led Sales-Led | I5: Đúng 1 kênh trong 90 ngày.
A6: Gross Margin (từ tab 2_Pricing) | B6: ='2_Pricing'!B21 -> 0.68385185 | G6: Người bán | H6: Đinh Xuân Quyền | I6: Chưa có đội sales.
A7: Phân khúc (SMB / Mid / Enterprise) | B7: SMB | G7: Tìm hiểu / opportunity ($) | H7: 24 | I7: 6 giờ x $4.
A8: → CAC payback cho phép (tháng) | B8: =IF(B7="SMB",12,IF(B7="Mid",18,24)) -> 12 | C8: tháng | D8: Bessemer, Scaling to $100M (2024) | G8: Demo / opportunity ($) | H8: 16 | I8: 4 giờ x $4.
A9: ★ NGÂN SÁCH CAC / khách | B9: =B5*B6*B8 -> 1329.408 | D9: ARPU × GM × số tháng payback | G9: Đi lại / opportunity ($) | H9: 20 | I9: Gom khách cùng địa bàn.
A10: → ACV (giá trị hợp đồng / năm) | B10: =B5*12 -> 1944 | G10: Công cụ / opportunity ($) | H10: 20 | I10: CRM/email/call phân bổ.
G11: CPO tính lại ($) | H11: =SUM(H7:H10) -> 80 | I11: Khớp B20, chưa phải số đo.
A12: B. SALES VIABILITY — một AE phải chốt bao nhiêu deal? | G12: Payback CAC giả định (tháng) | H12: =B22/(B5*B6) -> 2.8885038 | I12: Không chứng minh retention hoặc LTV.
A13: Quota / AE / năm ($) | B13: 60000 | D13: Quota $60k/năm là giả định motion nhỏ tại VN; không dùng mặc định $500k. | G13: CPO tối đa theo ngân sách CAC ($) | H13: =B9*B21 -> 332.352 | I13: Với win rate 25%.
A14: Số ngày làm việc / năm | B14: 250 | C14: ngày | G14: Win rate tối thiểu với CPO này | H14: =B20/B9 -> 0.060177162 | I14: Cần kiểm chứng bằng funnel thật.
A15: → Số deal / AE / năm | B15: =IF(B10=0,0,B13/B10) -> 30.864198
A16: ★ Số deal / AE / NGÀY | B16: =IF(B14=0,0,B15/B14) -> 0.12345679 | C16: deal/ngày | G16: Loaded AE / năm ($) | H16: 10000 | I16: Giả định, chưa tuyển.
A17: → Kết luận Sales-Led | B17: =IF(B16<=1,"KHẢ THI về mặt số học","BẤT KHẢ THI — ACV quá thấp để nuôi sales rep") -> KHẢ THI về mặt số học | G17: Deal/năm đạt quota | H17: =B15 -> 30.864198
G18: Chi phí AE/deal nếu đạt quota ($) | H18: =H16/H17 -> 324 | I18: Chưa travel/marketing; phép kiểm tra riêng không cộng trùng CAC founder.
A19: C. ĐỐI CHIẾU CAC THỰC TẾ CỦA MOTION CÓ SALES | G19: Chưa tuyển AE vì | H19: Thiếu bằng chứng sales và ngân sách | I19: Chỉ tuyển sau khi đo conversion, support, churn.
A20: Cost per opportunity ($) | B20: 80 | D20: CPO giả định: $24 prospect + $16 demo + $20 đi lại + $20 công cụ.
A21: Win rate | B21: 0.25 | G21: Prospect 90 ngày | H21: 200 | I21: Mục tiêu, không phải khách hiện có.
A22: → CAC thực tế ước tính / khách | B22: =IF(B21=0,0,B20/B21) -> 320 | G22: Qualified opportunities | H22: 20 | I22: 10% prospect, giả định.
A23: ★ Lệch bao nhiêu lần so với ngân sách CAC? | B23: =IF(B9=0,0,B22/B9) -> 0.24070865 | D23: Đây là bằng chứng chọn kênh của bạn | G23: Khách trả phí ngày 90 | H23: 5 | I23: 25% opportunity, bao gồm pilot chuyển trả phí.
A24: → Kết luận | B24: =IF(B23<=1,"Motion có sales KHẢ THI",IF(B23<=3,"Căng — cần tăng giá hoặc giảm chi phí bán hàng","KHÔNG KHẢ THI — đi PLG hoặc Partner-Led")) -> Motion có sales KHẢ THI | G24: Ngân sách acquisition 90 ngày ($) | H24: =H22*H11 -> 1600 | I24: Gồm giá trị thời gian founder.
G25: CAC từ kế hoạch ($) | H25: =H24/H23 -> 320 | I25: Khớp B22, chưa đo.
A26: D. CHẤM ĐIỂM 3 KÊNH (1 = rất kém, 5 = rất tốt) | G26: Quan hệ hiện tại | H26: Chưa có khách/pilot/partner xác nhận | I26: Không bịa tên công ty hoặc trạng thái liên hệ.
A27: Tiêu chí | B27: PLG | C27: Sales-Led | D27: Partner-Led
A28: 1. Ngân sách CAC của tôi nuôi nổi kênh này | B28: 2 | C28: 4 | D28: 2
A29: 2. Khách hàng mục tiêu thực sự mua theo cách này | B29: 2 | C29: 4 | D29: 3
A30: 3. Đội hiện tại có năng lực chạy kênh này ngay | B30: 2 | C30: 4 | D30: 1
A31: 4. Tôi tiếp cận được điểm nhúng / partner trong 30 ngày | B31: 2 | C31: 3 | D31: 1
A32: 5. Kênh này đưa tôi đến ĐÚNG Pain Moment | B32: 3 | C32: 4 | D32: 3
A33: 6. Tôi đo được hiệu quả trong vòng 90 ngày | B33: 3 | C33: 4 | D33: 2
A34: → TỔNG ĐIỂM | B34: =SUM(B28:B33) -> 14 | C34: =SUM(C28:C33) -> 23 | D34: =SUM(D28:D33) -> 12
A35: → Kênh điểm cao nhất | B35: =IF(AND(B34>=C34,B34>=D34),"PLG",IF(C34>=D34,"Sales-Led","Partner-Led")) -> Sales-Led
A37: E. CHỐT KÊNH
A38: ★ Kênh tôi chọn cho 90 ngày đầu | B38: Sales-Led | D38: ĐÚNG 1 kênh. Chọn 2 kênh trở lên bị trừ điểm.
A39: Nếu Partner-Led: TÊN CÔNG TY partner | B39: Không áp dụng | D39: 'Các nền tảng trong ngành' = chưa có kênh
A40: Đã nói chuyện với họ chưa? (Rồi / Chưa) | B40: Chưa
A41: Bạn mang lại giá trị gì cho partner? | B41: Chưa có partner; không dùng Partner-Led trong 90 ngày.
A42: Nếu rơi vào vùng không khả thi — lối thoát nào? | B42: Founder trực tiếp discovery/demo/chốt pilot trong một ngách PMS, chưa tuyển sales rep. | D42: Giảm giá để tự phục vụ / tăng giá + service / Partner-Led

Sheet 5_90Day_Plan
A1: TAB 5 — PAIN MOMENT · 90-DAY PLAN · EVIDENCE PACK
A2: Trạm 5 và Trạm 6.
A4: A. PAIN MOMENT — phải đủ 3 phần | G4: GATE CHUYỂN SANG VẬN HÀNH
A5: MẤY GIỜ khách đau nhất? | B5: 14:00-16:00 ngày nhiều khách đến, giả thuyết cần phỏng vấn. | G5: Đã biết | H5: Thiết kế job và event bài trước | I5: Không có xác nhận code/log/eval đã chạy.
A6: Lúc đó họ ĐANG LÀM GÌ? | B6: Khách đã có booking chờ nhập giấy tờ, xác thực và gán phòng tại lễ tân. | G6: Eval 200 hợp lệ | H6: CCCD/passport, ánh sáng, tuổi đa dạng | I6: Ghi Wilson CI; 200 ca không chứng minh tỷ lệ lỗi hiếm.
A7: Họ đang DÙNG APP / KÊNH NÀO? | B7: Quầy lễ tân + PMS khách sạn; khách giữ mã/QR booking trên điện thoại. | G7: Eval 100 lỗi/attack | H7: Sai người, ảnh in, replay, ảnh mờ | I7: 0 false accept trong tập test không có nghĩa 0 rủi ro thực.
A8: → Điểm nhúng cụ thể của bạn | B8: Web kiosk /check-in/booking tại sảnh -> eKYC -> Mews Connector API reservations/start -> xác nhận Started và AssignedResourceId. PMS dự kiến, chưa có quyền API. | D8: Một bề mặt tích hợp có tên, không phải 'website của chúng tôi' | G8: Containment | H8: Auto-PASS / tất cả phiên đủ điều kiện | I8: Gồm bỏ dở sau bắt đầu API; retry không tăng mẫu số.
G9: NSM | H9: Số arrival hoàn tất tự động/tháng | I9: Không phải tỷ lệ, dedupe theo case_id.
A10: B. 90-DAY PLAN | G10: Activation | H10: room_assigned trong <=3 phút | I10: Khác containment; chưa có số đo latency.
B11: THÁNG 1 — Học | C11: THÁNG 2–3 — Đòn bẩy | D11: THÁNG 4+ — Mở rộng | G11: STP | H11: Hoàn tất không retry / phiên bắt đầu | I11: Auto-PASS có retry không là STP.
A12: Kênh sử dụng | B12: Sales-Led, founder trực tiếp | C12: Cùng Sales-Led, không thêm kênh | D12: Giữ Sales-Led, chỉ mở ngách sau gate | G12: Retry chi phí | H12: Extra billed API / initial API cost | I12: 8% x1 vòng đầy đủ chỉ là dự phòng, phải đo từng API.
A13: Mục tiêu số khách | B13: 10 interviews, 2 hotel đồng ý pilot | C13: 5 khách trả phí lũy kế ngày 90 | D13: 10 khách trả phí sau ngày 90, chưa đạt | G13: False accept | H13: Không Auto-PASS attack đã biết | I13: Không hạ ngưỡng xác thực để containment đẹp.
A14: Việc cụ thể 1 | B14: 09/10-07/11/2026: 10 phỏng vấn; xác minh hotel dùng Mews, quyền demo/production, điều kiện phòng sẵn sàng. | C14: 08/11/2026-06/01/2027: 200 prospect -> 20 qualified opportunities | D14: Kiểm tra economics theo hóa đơn cohort>=4, không dùng cohort10 để kết luận pilot | G14: Trước pilot | H14: PMS, thiết bị, owner, dữ liệu rõ ràng | I14: Chưa có tên hotel: không ghi đã ký/chạy.
A15: Việc cụ thể 2 | B15: Eval 200 ca hợp lệ + 100 ca lỗi/tấn công; chưa có dữ liệu thật | C15: 2 hotel x >=200 phiên; báo cáo containment, retry, p50/p95 | D15: Chỉ mở hotel cùng PMS; chưa mở PMS mới khi connector/QA chưa ổn | G15: Lịch kế hoạch | H15: 09/10/2026-06/01/2027 | I15: 90 ngày; không phải lịch đã được khách chấp thuận.
A16: Việc cụ thể 3 | B16: Chốt dữ liệu, quyền API, chi phí connector và protocol trước pilot; hotel có thiết bị và phòng gán sẵn. | C16: Đo công lễ tân trước/sau, usage ledger, phê duyệt giá | D16: Nếu support>1.5 giờ/hotel/tháng, phải tính lại phí nền | G16: Ngân sách học | H16: $500 kế hoạch, chưa chi | I16: Dừng/đánh giá lại nếu vượt budget hoặc false accept nghiêm trọng.
A17: KPI đo được | B17: 10 interviews; eval hoàn tất; 2 pilot có chấp thuận | C17: Mục tiêu containment>=85%, p95<=3 phút; 5 paid; CAC trong ngân sách | D17: GM>=60% trong 2 tháng; không auto-PASS attack đã biết; đo retention | G17: Test người lạ | H17: Đã test với Đỗ Trường Thành Ân | I17: 12:10 08/10/2026; đọc 2 phút theo quy trình người học cung cấp, đủ 3 ý; 2 câu hỏi lại.
A18: Người chịu trách nhiệm | B18: Đinh Xuân Quyền | C18: Đinh Xuân Quyền; phía hotel chưa xác nhận | D18: Đinh Xuân Quyền
A19: Tháng 1 là giai đoạn HỌC, không phải scale. Kế hoạch 'tháng 1 lấy 200 khách ở 5 ngành' là kế hoạch chưa ai từng thử làm. | G19: ĐỐI CHIẾU EVAL THỰC TẾ
G20: Case auto-PASS thực đo | H20: Chưa đo | I20: Chỉ điền số nguyên từ log; chưa có dữ liệu eval.
A21: C. EVIDENCE PACK — 3 tài sản bán hàng | G21: Case đủ điều kiện thực đo | H21: Chưa đo | I21: Cùng tập dữ liệu; gồm bỏ dở/PMS lỗi sau bắt đầu API.
A22: Tài sản | B22: Đã có? (Rồi/Chưa) | C22: Nội dung 1 câu — hoặc việc cần làm | D22: Người phụ trách · Deadline | G22: Containment thực đo | H22: =IF(AND(ISNUMBER(H20),ISNUMBER(H21)),IF(AND(H21>0,H20>=0,H20<=H21),H20/H21,"Dữ liệu không hợp lệ"),"Chưa đo") -> Chưa đo | I22: Không thay 85% giả định bằng kết quả chưa chạy.
A23: 1. Eval Results | B23: Chưa | C23: Eval 300 ca: containment, false accept/reject, OCR exact match, retry và p95. | D23: Đinh Xuân Quyền · 22/10/2026 | G23: So với ngưỡng giá trị khách | H23: =IF(ISNUMBER(H22),IF(H22>='2_Pricing'!H24,"Đạt ngưỡng ROI kế hoạch","Dưới ngưỡng ROI kế hoạch"),"Chưa đủ dữ liệu") -> Chưa đủ dữ liệu | I23: Đối chiếu tham khảo với economics N hiện tại; không là quyết định release.
A24: 2. Risk Checklist | B24: Chưa | C24: Q&A về nhận nhầm/giả mạo, dữ liệu, xuất/xóa dữ liệu; xác nhận cấu hình trước pilot. | D24: Đinh Xuân Quyền · 29/10/2026 | G24: Hạn hoàn thành eval | H24: 22/10/2026 | I24: Đinh Xuân Quyền; xem Evidence_Pack.md và Eval_Protocol.csv.
A25: 3. Pilot Report | B25: Chưa | C25: Protocol 2 hotel x >=200 phiên; chưa có tên hotel hay kết quả thực. | D25: Đinh Xuân Quyền · 06/01/2027 | G25: PMS dự kiến | H25: Mews Connector API | I25: Mới xác minh tài liệu; chưa gọi API, chưa có hotel chấp thuận.
A26: Ô nào CHƯA CÓ thì ghi deadline — đừng bỏ trống. Thành thật về khoảng trống được điểm cao hơn bịa nội dung. | G26: Hạn xác minh quyền và chi phí PMS | H26: 22/10/2026 | I26: Owner: Đinh Xuân Quyền; chưa đăng ký/liên hệ, chưa có báo giá.
G27: Test người lạ | H27: Đạt: đủ 3 ý, hỏi lại 2 câu | I27: 12:10 08/10/2026. Kết quả theo người học xác nhận; xem Test_Nguoi_La.md.
A28: D. BÀI TEST NGƯỜI LẠ — nhóm khác đọc One-Pager trong 2 phút
A29: Họ trả lời được: bán gì, cho ai, tính tiền theo đơn vị nào? (Được/Không) | B29: Được | D29: Khách sạn trả tiền; $30/tháng + $0.11/hồ sơ đủ điều kiện; retry/duplicate không thu thêm.
A30: Họ trả lời được: có lãi trên mỗi đơn vị không, số nào chứng minh? (Được/Không) | B30: Được | D30: Nêu doanh thu $162, COGS $51.216, GM68.39%; hiểu đây là giả định cohort10, chưa là pilot.
A31: Họ trả lời được: tiếp cận khách qua đâu, vì sao kênh đó? (Được/Không) | B31: Được | D31: Sales-Led vì cần trao đổi buyer và tích hợp PMS; CAC$320 so ngân sách$1,329.41, chưa đo.
A32: Số câu họ phải hỏi lại (mục tiêu ≤ 3) | B32: 2 | D32: Ân - 2A202602899; 12:10 08/10/2026; theo quy trình đọc2 phút. Biên bản: Test_Nguoi_La.md.

Sheet 6_Benchmarks
A1: TAB 6 — BENCHMARKS (CHỈ ĐỌC)
A2: A:E là giá mẫu lịch sử, không dùng. SmartCheck-in dùng nguồn G:J, kiểm tra 08/10/2026.
A3: NGÀY BẠN KIỂM TRA LẠI GIÁ | B3: 46303 | D3: Bắt buộc điền — Rubric có chấm mục này
G4: NGUỒN ÁP DỤNG TRONG BÀI
A5: Nhóm | B5: Mục | C5: Giá | D5: Đơn vị | E5: Nguồn | G5: Mục | H5: Mức áp dụng | I5: Nguồn chính thức | J5: Giới hạn
A6: LLM | B6: Claude Opus 5 — input / output | C6: 5,00 / 25,00 | D6: $ / 1M token | E6: platform.claude.com/docs/en/about-claude/pricing | G6: Google Vision OCR | H6: $1.50 / 1000 ảnh | I6: https://cloud.google.com/vision/pricing | J6: Document Text Detection, không trừ free tier.
A7: LLM | B7: Claude Sonnet 5 — input / output | C7: 2,00 / 10,00 | D7: $ / 1M token | E7: platform.claude.com/docs/en/about-claude/pricing | G7: OCR tiếng Việt | H7: vi được hỗ trợ | I7: https://docs.cloud.google.com/vision/docs/languages | J7: Không tự đảm bảo chính xác CCCD.
A8: LLM | B8: Claude Haiku 4.5 — input / output | C8: 1,00 / 5,00 | D8: $ / 1M token | E8: platform.claude.com/docs/en/about-claude/pricing | G8: AWS Group1/2 | H8: $0.001 / ảnh bậc đầu | I8: https://aws.amazon.com/rekognition/pricing/ | J8: CompareFaces nhóm1, DetectFaces nhóm2; tham chiếu US.
A9: LLM | B9: Claude — cache write 5' / cache read | C9: 1,25× / 0,10× input | D9: hệ số | E9: platform.claude.com/docs/en/about-claude/pricing | G9: AWS Liveness | H9: $0.015 / check | I9: https://aws.amazon.com/rekognition/pricing/ | J9: US East N.Virginia, 500k đầu; region thực chưa chốt.
A10: LLM | B10: ⏳ OpenAI GPT-5.6 Sol — input / output | C10: 4,00 / 20,00 | D10: $ / 1M token | E10: developers.openai.com/api/docs/pricing (KM 21/08–21/11/2026; list 5,00/30,00) | G10: Chekin | H10: Từ €3.95/property/tháng (năm) | I10: https://chekin.com/en/pricing/ | J10: Mức từ theo thanh toán năm; vacation rental, hotel cần báo giá.
A11: LLM | B11: OpenAI GPT-5.6 Luna — input / output | C11: 0,20 / 1,20 | D11: $ / 1M token | E11: developers.openai.com/api/docs/pricing | G11: Duve Basic | H11: Tối thiểu $120/tháng | I11: https://duve.com/pricing/ | J11: Online check-in/guest app; automation có phụ phí.
A12: LLM | B12: OpenAI — cached input / Batch API | C12: 10% input / −50% | D12: hệ số | E12: developers.openai.com/api/docs/pricing | G12: FX kế hoạch | H12: 26000 VND/USD | I12: Giả định nội bộ 08/10/2026 | J12: Không phải tỷ giá giao dịch hiện hành.
A13: LLM | B13: Gemini 3.1 Pro — input / output (≤200k) | C13: 2,00 / 12,00 | D13: $ / 1M token | E13: ai.google.dev/gemini-api/docs/pricing | G13: CAC/lương/hosting | H13: Giả định kế hoạch | I13: README.md và các ô G:H | J13: Không là benchmark thị trường Việt Nam.
A14: LLM | B14: ⏳ Gemini 3.7 Flash — input / output | C14: 0,75 / 3,75 | D14: $ / 1M token | E14: ai.google.dev/gemini-api/docs/pricing (KM đến 31/12/2026; sau đó 1,50/7,50) | G14: Ngày kiểm tra | H14: 08/10/2026 | I14: Trang giá chính thức ở trên | J14: Không dùng free tier hoặc giá khuyến mại.
A15: STT | B15: Deepgram Nova-3 — pre-recorded | C15: 0,0043 | D15: $ / phút | E15: deepgram.com/pricing
A16: STT | B16: ⏳ Deepgram Nova-3 — streaming | C16: list 0,0077 · KM 0,0048 | D16: $ / phút | E16: deepgram.com/pricing — đang khuyến mại, kiểm tra lại
A17: STT | B17: AssemblyAI Universal-2 — async | C17: 0,0025 | D17: $ / phút | E17: assemblyai.com/pricing
A18: STT | B18: OpenAI gpt-4o-mini-transcribe | C18: 0,0030 | D18: $ / phút | E18: developers.openai.com/api/docs/pricing
A19: TTS | B19: Google Cloud TTS — Standard | C19: 4,00 | D19: $ / 1M ký tự | E19: cloud.google.com/text-to-speech/pricing (rẻ nhất)
A20: TTS | B20: OpenAI tts-1 | C20: 15,00 | D20: $ / 1M ký tự | E20: developers.openai.com/api/docs/pricing
A21: TTS | B21: ElevenLabs Flash / Turbo | C21: 50,00 | D21: $ / 1M ký tự | E21: elevenlabs.io/pricing/api
A22: TTS | B22: ElevenLabs v3 / v2 Multilingual | C22: 100,00 | D22: $ / 1M ký tự | E22: elevenlabs.io/pricing/api
A23: Quy đổi | B23: Tốc độ nói | C23: ≈ 900 | D23: ký tự / phút | E23: ≈150 từ/phút — dùng để đổi phút ↔ ký tự
A24: Lưu ý | B24: Google TTS — ký tự CJK | C24: tính là 1 ký tự | D24: — | E24: cloud.google.com/text-to-speech/pricing (KHÔNG phải ×2)
A25: Lưu ý | B25: Google STT — tính theo kênh | C25: 4 kênh × 120s = 480s | D25: — | E25: cloud.google.com/speech-to-text/pricing
A26: Lưu ý | B26: Streaming vs async STT | C26: 1× đến ~5× | D26: hệ số | E26: Tuỳ nhà cung cấp — AssemblyAI 1,0× · Google ~5×. Đừng dùng hệ số chung
... A41: Benchmark | B41: ACV sàn cho inside sales | C41: ≈ 3.000 | D41: $ / năm | E41: Tomasz Tunguz (2016) — có kèm giả định để tính lại
A43: Lưu ý: trang marketing của nhà cung cấp có thể hiển thị giá cũ hơn trang docs. Ưu tiên trang docs / pricing chính thức.
